<?xml version="1.0" ?>
<!-- =================================================================================== -->
<!-- |    This document was autogenerated by xacro from first.xacro                    | -->
<!-- |    EDITING THIS FILE BY HAND IS NOT RECOMMENDED                                 | -->
<!-- =================================================================================== -->
<robot name="six_links">
  <link name="base">
    <visual>
      <origin rpy="0 0 0" xyz="0 0 0"/>
      <geometry>
        <box size="1 1 1"/>
      </geometry>
    </visual>
  </link>
  <!-- <link name="base">
        <visual>
            <origin rpy="0.0 0.0 0.0" xyz="0.0 0.0 0.0"/>
            <geometry>
                <box size="1.0 1.0 1.0"/>
            </geometry>
        </visual>
    </link> -->
  <joint name="base_link1" type="revolute">
    <origin rpy="0 0 0" xyz="0 0 0.5"/>
    <parent link="base"/>
    <child link="link1"/>
    <axis xyz="0 0 1"/>
    <limit effort="1000" lower="-3.14" upper="3.14" velocity="0.5"/>
  </joint>
  <!-- <joint name="base_link1" type="revolute">
        <origin rpy="0.0 0.0 0.0" xyz="0.0 0.0 0.5"/>
        <parent link="base"/>
        <child link="link1"/>
        <axis xyz="0.0 0.0 1.0"/>
        <!- 3.14 is pi=180 degrees ->
        <limit lower="-3.14" upper="3.14" effort="1000.0" velocity="0.5"/>
    </joint> -->
  <link name="link1">
    <visual>
      <origin rpy="0 0 0" xyz="0 0 0.2"/>
      <geometry>
        <cylinder length="0.4" radius="0.35"/>
      </geometry>
    </visual>
  </link>
  <!-- <link name="link1">
        <visual>
            <origin rpy="0.0 0.0 0.0" xyz="0.0 0.0 0.2"/>
            <geometry>
                <cylinder radius="0.35" length="0.4"/>
            </geometry>
        </visual>
    </link> -->
  <joint name="link1_link2" type="revolute">
    <origin rpy="0 0 0" xyz="0 0 0.4"/>
    <parent link="link1"/>
    <child link="link2"/>
    <axis xyz="0 1 0"/>
    <limit effort="1000" lower="-3.14" upper="3.14" velocity="0.5"/>
  </joint>
  <!-- <joint name="link1_link2" type="revolute">
        <origin xyz="0.0 0.0 0.4" rpy="0.0 0.0 0.0"/>
        <parent link="link1"/>
        <child link="link2"/>
        <axis xyz="0.0 1.0 0.0"/>
        <limit lower="-3.14" upper="3.14" effort="1000.0" velocity="0.5"/>
    </joint> -->
  <link name="link2">
    <visual>
      <origin rpy="0 0 0" xyz="0 0 0.4"/>
      <geometry>
        <cylinder length="0.8" radius="0.15"/>
      </geometry>
    </visual>
  </link>
  <!-- <link name="link2">
        <visual>
            <origin xyz="0.0 0.0 0.4" rpy="0.0 0.0 0.0"/>
            <geometry>
                <cylinder radius="0.15" length="0.8"/>
            </geometry>
        </visual>
    </link> -->
</robot>

