<?xml version="1.0" ?>
<!-- =================================================================================== -->
<!-- |    This document was autogenerated by xacro from env.xacro                      | -->
<!-- |    EDITING THIS FILE BY HAND IS NOT RECOMMENDED                                 | -->
<!-- =================================================================================== -->
<robot name="env">
  <link name="ground">
    <visual>
      <origin rpy="0 0 0" xyz="0 0 0"/>
      <geometry>
        <box size="5 5 0.1"/>
      </geometry>
    </visual>
    <inertial>
      <origin rpy="0 0 0" xyz="0 0 0"/>
      <mass value="57.906"/>
      <inertia ixx="12.679" ixy="0" ixz="0" iyy="12.679" iyz="0" izz="0.651"/>
    </inertial>
    <collision>
      <origin rpy="0 0 0" xyz="0 0 0"/>
      <geometry>
        <box size="5 5 0.1"/>
      </geometry>
    </collision>
  </link>
  <joint name="ground_stand" type="fixed">
    <origin rpy="0 0 0" xyz="0 0 0"/>
    <parent link="ground"/>
    <child link="stand"/>
  </joint>
  <!-- <xacro:m_transmission joint="ground_stand" /> -->
  <link name="stand">
    <visual>
      <origin rpy="0 0 0" xyz="0 0 2.5"/>
      <geometry>
        <box size="0.3 0.3 5"/>
      </geometry>
    </visual>
    <inertial>
      <origin rpy="0 0 0" xyz="0 0 2.5"/>
      <mass value="57.906"/>
      <inertia ixx="12.679" ixy="0" ixz="0" iyy="12.679" iyz="0" izz="0.651"/>
    </inertial>
    <collision>
      <origin rpy="0 0 0" xyz="0 0 2.5"/>
      <geometry>
        <box size="0.3 0.3 5"/>
      </geometry>
    </collision>
  </link>
  <joint name="stand_base" type="fixed">
    <origin rpy="0 0 0" xyz="0 0 4"/>
    <parent link="stand"/>
    <child link="base"/>
  </joint>
  <link name="base">
    <visual>
      <origin rpy="1.57 0 0" xyz="0 -1.16 0"/>
      <geometry>
        <cylinder length="2" radius="0.35"/>
      </geometry>
    </visual>
    <inertial>
      <origin rpy="1.57 0 0" xyz="0 -1.16 0"/>
      <mass value="57.906"/>
      <inertia ixx="12.679" ixy="0" ixz="0" iyy="12.679" iyz="0" izz="0.651"/>
    </inertial>
    <collision>
      <origin rpy="1.57 0 0" xyz="0 -1.16 0"/>
      <geometry>
        <cylinder length="2" radius="0.35"/>
      </geometry>
    </collision>
  </link>
  <joint name="base_dummy" type="revolute">
    <origin rpy="0 0 0" xyz="0 -2.16 0"/>
    <parent link="base"/>
    <child link="dummy"/>
    <axis xyz="0 1 0"/>
    <limit effort="1000" lower="-3.14" upper="3.14" velocity="0.5"/>
  </joint>
  <transmission name="trans_base_dummy">
    <type>transmission_interface/SimpleTransmission</type>
    <joint name="base_dummy">
      <hardwareInterface>hardware_interface/PositionJointInterface</hardwareInterface>
    </joint>
    <actuator name="motor_base_dummy">
      <hardwareInterface>hardware_interface/PositionJointInterface</hardwareInterface>
      <mechanicalReduction>1</mechanicalReduction>
    </actuator>
  </transmission>
  <link name="dummy">
    <visual>
      <origin rpy="0 0 0" xyz="0 0 0"/>
      <geometry>
        <cylinder length="0.01" radius="0.01"/>
      </geometry>
    </visual>
    <inertial>
      <origin rpy="0 0 0" xyz="0 0 0"/>
      <mass value="0.01"/>
      <inertia ixx="12.679" ixy="0" ixz="0" iyy="12.679" iyz="0" izz="0.651"/>
    </inertial>
    <collision>
      <origin rpy="0 0 0" xyz="0 0 0"/>
      <geometry>
        <cylinder length="0.01" radius="0.01"/>
      </geometry>
    </collision>
  </link>
  <joint name="dummy_link" type="revolute">
    <origin rpy="0 0 0" xyz="0 0 0"/>
    <parent link="dummy"/>
    <child link="link"/>
    <axis xyz="1 0 0"/>
    <limit effort="1000" lower="-3.14" upper="3.14" velocity="0.5"/>
  </joint>
  <transmission name="trans_dummy_link">
    <type>transmission_interface/SimpleTransmission</type>
    <joint name="dummy_link">
      <hardwareInterface>hardware_interface/PositionJointInterface</hardwareInterface>
    </joint>
    <actuator name="motor_dummy_link">
      <hardwareInterface>hardware_interface/PositionJointInterface</hardwareInterface>
      <mechanicalReduction>1</mechanicalReduction>
    </actuator>
  </transmission>
  <link name="link">
    <visual>
      <origin rpy="0 0 0" xyz="0 -0.36 -1"/>
      <geometry>
        <cylinder length="2" radius="0.35"/>
      </geometry>
    </visual>
    <inertial>
      <origin rpy="0 0 0" xyz="0 -0.36 -1"/>
      <mass value="57.906"/>
      <inertia ixx="12.679" ixy="0" ixz="0" iyy="12.679" iyz="0" izz="0.651"/>
    </inertial>
    <collision>
      <origin rpy="0 0 0" xyz="0 -0.36 -1"/>
      <geometry>
        <cylinder length="2" radius="0.35"/>
      </geometry>
    </collision>
  </link>
  <!-- Add gazebo plugin at end of the file as we are adding gazebo controllers -->
  <gazebo>
    <plugin filename="libgazebo_ros_control.so" name="gazebo_ros_control"/>
  </gazebo>
  <!-- cd construct_ws/src/robot_manipulator/urdf/model & check_urdf <(xacro env.xacro) -->
</robot>

